<?xml version="1.0"?>
<robot xmlns:xacro="http://www.ros.org/wiki/xacro">

    <xacro:include filename="inertial.xacro"/>

    <!-- ######## COLORS ######## -->

    <material name="white">
        <color rgba="1 1 1 1" />
    </material>

    <material name="orange">
        <color rgba="1 0.3 0.1 1"/>
    </material>

    <material name="blue">
        <color rgba="0.2 0.2 1 1"/>
    </material>

    <material name="black">
        <color rgba="0 0 0 1"/>
    </material>

    <material name="red">
        <color rgba="1 0 0 1"/>
    </material>

    <!-- BASE LINK-->
    <link name="base_link">

    </link>

    <!-- ######## CHASSIS ######## -->

    <!-- JOINT -->
    <joint name="chassis_joint" type="fixed">
        <parent link="base_link"/>
        <child link="chassis"/>
        <origin xyz="0 0 0.03"/>
    </joint>

    <!-- LINK -->
    <link name="chassis">
        <visual>
            <origin xyz="0 0 0" rpy="0 0 0"/>
            <geometry>
                <cylinder radius="0.125" length="0.006"/>
            </geometry>
            <material name="white"/>
        </visual>
        <collision>
            <origin xyz="0 0 0" rpy="0 0 0"/>
            <geometry>
                <cylinder radius="0.125" length="0.006"/>
            </geometry>
        </collision>
        <xacro:inertial_cylinder mass="0.5" length="0.006" radius="0.125">
            <origin xyz="0 0 0" rpy="0 0 0"/>
        </xacro:inertial_cylinder>         
    </link>

    <!-- ######## PLATFORM 1 ######## -->

    <!-- JOINT -->
    <joint name="platform1_joint" type="fixed">
        <parent link="chassis"/>
        <child link="platform1"/>
        <origin xyz="0 0 0.07"/>
    </joint>

    <!-- LINK -->
    <link name="platform1">
        <visual>
            <origin xyz="0 0 0" rpy="0 0 0"/>
            <geometry>
                <cylinder radius="0.125" length="0.006"/>
            </geometry>
            <material name="white"/>
        </visual>
    </link>

    <!-- ######## PLATFORM 2 ######## -->

    <!-- JOINT -->
    <joint name="platform2_joint" type="fixed">
        <parent link="chassis"/>
        <child link="platform2"/>
        <origin xyz="0 0 0.14"/>
    </joint>

    <!-- LINK -->
    <link name="platform2">
        <visual>
            <origin xyz="0 0 0" rpy="0 0 0"/>
            <geometry>
                <cylinder radius="0.125" length="0.006"/>
            </geometry>
            <material name="white"/>
        </visual>
    </link>

    <!-- ######## PLATFORM 3 ######## -->

    <!-- JOINT -->
    <joint name="platform3_joint" type="fixed">
        <parent link="chassis"/>
        <child link="platform3"/>
        <origin xyz="0 0 0.21"/>
    </joint>

    <!-- LINK -->
    <link name="platform3">
        <visual>
            <origin xyz="0 0 0" rpy="0 0 0"/>
            <geometry>
                <cylinder radius="0.125" length="0.006"/>
            </geometry>
            <material name="white"/>
        </visual>
    </link>

    <!-- ######## LEFT WHEEL ######## -->

    <!-- JOINT -->
    <joint name="left_wheel_joint" type="continuous">
        <parent link="chassis"/>
        <child link="left_wheel"/>
        <origin xyz="0 0.150 -0.015" rpy="${pi/2} 0 0"/>
        <axis xyz="0 0 1"/>
    </joint>

    <!-- LINK -->
    <link name="left_wheel">
        <visual>
            <origin xyz="0 0 0" rpy="0 0 0"/>
            <geometry>
                <cylinder radius="0.05" length="0.05"/>
            </geometry>
            <material name="blue"/>
        </visual>
        <collision>
            <origin xyz="0 0 0" rpy="0 0 0"/>
            <geometry>
                <cylinder radius="0.05" length="0.05"/>
            </geometry>
        </collision>
        <xacro:inertial_cylinder mass="0.1" length="0.05" radius="0.05">
            <origin xyz="0 0 0" rpy="0 0 0"/>
        </xacro:inertial_cylinder>
    </link>

    <!-- ######## RIGHT WHEEL ######## -->

    <!-- JOINT -->
    <joint name="right_wheel_joint" type="continuous">
        <parent link="chassis"/>
        <child link="right_wheel"/>
        <origin xyz="0 -0.150 -0.015" rpy="${pi/2} 0 0"/>
        <axis xyz="0 0 -1"/>
    </joint>

    <!-- LINK -->
    <link name="right_wheel">
        <visual>
            <origin xyz="0 0 0" rpy="0 0 0"/>
            <geometry>
                <cylinder radius="0.05" length="0.05"/>
            </geometry>
            <material name="blue"/>
        </visual>
        <collision>
            <origin xyz="0 0 0" rpy="0 0 0"/>
            <geometry>
                <cylinder radius="0.05" length="0.05"/>
            </geometry>
        </collision>
        <xacro:inertial_cylinder mass="0.1" length="0.05" radius="0.05">
            <origin xyz="0 0 0" rpy="0 0 0"/>
        </xacro:inertial_cylinder>
    </link>

    <!-- ######## FRONT WHEEL ######## -->

    <!-- JOINT -->
    <joint name="front_wheel_joint" type="continuous">
        <parent link="chassis"/>
        <child link="front_wheel"/>
        <origin xyz="0.150 0 -0.015" rpy="0 ${pi/2} 0"/>
        <axis xyz="0 0 1"/>
    </joint>

    <!-- LINK -->
    <link name="front_wheel">
        <visual>
            <origin xyz="0 0 0" rpy="0 0 0"/>
            <geometry>
                <cylinder radius="0.05" length="0.05"/>
            </geometry>
            <material name="blue"/>
        </visual>
        <collision>
            <origin xyz="0 0 0" rpy="0 0 0"/>
            <geometry>
                <cylinder radius="0.05" length="0.05"/>
            </geometry>
        </collision>
        <xacro:inertial_cylinder mass="0.1" length="0.05" radius="0.05">
            <origin xyz="0 0 0" rpy="0 0 0"/>
        </xacro:inertial_cylinder>
    </link>

    <!-- ######## BACK WHEEL ######## -->

    <!-- JOINT -->
    <joint name="back_wheel_joint" type="continuous">
        <parent link="chassis"/>
        <child link="back_wheel"/>
        <origin xyz="-0.150 0 -0.015" rpy="0 ${pi/2} 0"/>
        <axis xyz="0 0 1"/>
    </joint>

    <!-- LINK -->
    <link name="back_wheel">
        <visual>
            <origin xyz="0 0 0" rpy="0 0 0"/>
            <geometry>
                <cylinder radius="0.05" length="0.05"/>
            </geometry>
            <material name="blue"/>
        </visual>
        <collision>
            <origin xyz="0 0 0" rpy="0 0 0"/>
            <geometry>
                <cylinder radius="0.05" length="0.05"/>
            </geometry>
        </collision>
        <xacro:inertial_cylinder mass="0.1" length="0.05" radius="0.05">
            <origin xyz="0 0 0" rpy="0 0 0"/>
        </xacro:inertial_cylinder>
    </link>

</robot>