<?xml version="1.0"?>
<robot xmlns:xacro="http://www.ros.org/wiki/xacro">

    <xacro:include filename="inertial.xacro"/>

    <!-- ######## COLORS ######## -->

    <material name="white">
        <color rgba="1 1 1 1" />
    </material>

    <material name="orange">
        <color rgba="1 0.3 0.1 1"/>
    </material>

    <material name="blue">
        <color rgba="0.2 0.2 1 1"/>
    </material>

    <material name="black">
        <color rgba="0 0 0 1"/>
    </material>

    <material name="red">
        <color rgba="1 0 0 1"/>
    </material>

    <!-- ######## BASE LINK ######## -->
    <link name="base_link">
    </link>

    <!-- ######## BASE FOOTPRINT ######## -->

    <joint name="base_footprint_joint" type="fixed">
        <parent link="base_link"/>
        <child link="base_footprint"/>
        <origin xyz="0 0 0" rpy="0 0 0"/>
    </joint>

    <link name="base_footprint">
    </link>

    <!-- ######## CHASSIS ######## -->

    <!-- JOINT -->
    <joint name="chassis_joint" type="fixed">
        <parent link="base_link"/>
        <child link="chassis"/>
        <origin xyz="0 0 0.03"/>
    </joint>

    <!-- LINK -->
    <link name="chassis">
        <visual>
            <origin xyz="0 0 0.105" rpy="0 0 0"/>
            <geometry>
                <cylinder radius="0.125" length="0.21"/>
            </geometry>
            <material name="white"/>
        </visual>
        <collision>
            <origin xyz="0 0 0" rpy="0 0 0"/>
            <geometry>
                <cylinder radius="0.125" length="0.21"/>
            </geometry>
        </collision>
        <xacro:inertial_cylinder mass="0.5" length="0.21" radius="0.125">
            <origin xyz="0 0 0" rpy="0 0 0"/>
        </xacro:inertial_cylinder>         
    </link>

    <!-- ######## LEFT WHEEL ######## -->

    <!-- JOINT -->
    <joint name="left_wheel_joint" type="continuous">
        <parent link="base_link"/>
        <child link="left_wheel"/>
        <origin xyz="0 0.150 0" rpy="${pi/2} 0 0"/>
        <axis xyz="0 0 1"/>
    </joint>

    <!-- LINK -->
    <link name="left_wheel">
        <visual>
            <origin xyz="0 0 0" rpy="0 0 0"/>
            <geometry>
                <cylinder radius="0.05" length="0.05"/>
            </geometry>
            <material name="blue"/>
        </visual>
        <collision>
            <origin xyz="0 0 0" rpy="0 0 0"/>
            <geometry>
                <cylinder radius="0.05" length="0.05"/>
            </geometry>
        </collision>
        <xacro:inertial_cylinder mass="0.1" length="0.05" radius="0.05">
            <origin xyz="0 0 0" rpy="0 0 0"/>
        </xacro:inertial_cylinder>
        
    </link>

    <gazebo reference="left_wheel">
        <material>Gazebo/Blue</material>
    </gazebo>

    <!-- ######## RIGHT WHEEL ######## -->

    <!-- JOINT -->
    <joint name="right_wheel_joint" type="continuous">
        <parent link="base_link"/>
        <child link="right_wheel"/>
        <origin xyz="0 -0.150 0" rpy="${pi/2} 0 0"/>
        <axis xyz="0 0 -1"/>
    </joint>

    <!-- LINK -->
    <link name="right_wheel">
        <visual>
            <origin xyz="0 0 0" rpy="0 0 0"/>
            <geometry>
                <cylinder radius="0.05" length="0.05"/>
            </geometry>
            <material name="blue"/>
        </visual>
        <collision>
            <origin xyz="0 0 0" rpy="0 0 0"/>
            <geometry>
                <cylinder radius="0.05" length="0.05"/>
            </geometry>
        </collision>
        <xacro:inertial_cylinder mass="0.1" length="0.05" radius="0.05">
            <origin xyz="0 0 0" rpy="0 0 0"/>
        </xacro:inertial_cylinder>
    </link>

    <gazebo reference="right_wheel">
        <material>Gazebo/Blue</material>
    </gazebo>

    <!-- ######## FRONT WHEEL ######## -->

    <!-- JOINT -->
    <joint name="front_wheel_joint" type="continuous">
        <parent link="base_link"/>
        <child link="front_wheel"/>
        <origin xyz="0.150 0 0" rpy="0 ${pi/2} 0"/>
        <axis xyz="0 0 1"/>
    </joint>

    <!-- LINK -->
    <link name="front_wheel">
        <visual>
            <origin xyz="0 0 0" rpy="0 0 0"/>
            <geometry>
                <cylinder radius="0.05" length="0.05"/>
            </geometry>
            <material name="blue"/>
        </visual>
        <collision>
            <origin xyz="0 0 0" rpy="0 0 0"/>
            <geometry>
                <cylinder radius="0.05" length="0.05"/>
            </geometry>
        </collision>
        <xacro:inertial_cylinder mass="0.1" length="0.05" radius="0.05">
            <origin xyz="0 0 0" rpy="0 0 0"/>
        </xacro:inertial_cylinder>
    </link>

    <gazebo reference="front_wheel">
        <material>Gazebo/Blue</material>
    </gazebo>

    <!-- ######## BACK WHEEL ######## -->

    <!-- JOINT -->
    <joint name="back_wheel_joint" type="continuous">
        <parent link="base_link"/>
        <child link="back_wheel"/>
        <origin xyz="-0.150 0 0" rpy="0 ${pi/2} 0"/>
        <axis xyz="0 0 1"/>
    </joint>

    <!-- LINK -->
    <link name="back_wheel">
        <visual>
            <origin xyz="0 0 0" rpy="0 0 0"/>
            <geometry>
                <cylinder radius="0.05" length="0.05"/>
            </geometry>
            <material name="blue"/>
        </visual>
        <collision>
            <origin xyz="0 0 0" rpy="0 0 0"/>
            <geometry>
                <cylinder radius="0.05" length="0.05"/>
            </geometry>
        </collision>
        <xacro:inertial_cylinder mass="0.1" length="0.05" radius="0.05">
            <origin xyz="0 0 0" rpy="0 0 0"/>
        </xacro:inertial_cylinder>
    </link>

    <gazebo reference="back_wheel">
        <material>Gazebo/Blue</material>
    </gazebo>

</robot>